Workbook

Sheet Horizontal Analysis
A1: Consolidated Balance Sheets Delta Airlines- USD ($) | B1: Dec. 31, 2024 | C1: Dec. 31, 2023 | D1: Dollar Change | E1: Percent Change | G1: Consolidated Statements of Operations Delta Airlines- USD ($) | H1: 12 Months Ended | J1: Dollar Change | K1: Percent Change
A2: $ in Millions | G2: $ in Millions | H2: Dec. 31, 2024 | I2: Dec. 31, 2023
A3: Current Assets: | G3: Operating Revenue:
A4: Cash and cash equivalents | B4: 3069 | C4: 2741 | D4: =B4-C4 -> 328 | E4: =D4/C4 -> 0.11966436 | G4: Total operating revenue | H4: 61643 | I4: 58048 | J4: =H4-I4 -> 3595 | K4: =J4/I4 -> 0.061931505
A5: Short-term investments | B5: 0 | C5: 1127 | D5: =B5-C5 -> -1127 | E5: =D5/C5 -> -1 | G5: Operating Expense:
A6: Accounts receivable, net of an allowance for uncollectible accounts of $18 and $17 | B6: 3224 | C6: 3130 | D6: =B6-C6 -> 94 | E6: =D6/C6 -> 0.030031949 | G6: Salaries and related costs | H6: 16161 | I6: 14607 | J6: =H6-I6 -> 1554 | K6: =J6/I6 -> 0.10638735
A7: Fuel, expendable parts and supplies inventories, net of an allowance for obsolescence of $120 and $123 | B7: 1428 | C7: 1314 | D7: =B7-C7 -> 114 | E7: =D7/C7 -> 0.086757991 | G7: Aircraft fuel and related taxes | H7: 10566 | I7: 11069 | J7: =H7-I7 -> -503 | K7: =J7/I7 -> -0.045442226
A8: Prepaid expenses and other | B8: 2123 | C8: 1957 | D8: =B8-C8 -> 166 | E8: =D8/C8 -> 0.08482371 | G8: Ancillary businesses and refinery | H8: 5416 | I8: 4172 | J8: =H8-I8 -> 1244 | K8: =J8/I8 -> 0.29817833
A9: Total current assets | B9: 9844 | C9: 10269 | D9: =B9-C9 -> -425 | E9: =D9/C9 -> -0.041386698 | G9: Contracted services | H9: 4228 | I9: 4041 | J9: =H9-I9 -> 187 | K9: =J9/I9 -> 0.046275674
A10: Noncurrent Assets: | G10: Landing fees and other rents | H10: 3150 | I10: 2563 | J10: =H10-I10 -> 587 | K10: =J10/I10 -> 0.22902848
A11: Property and equipment, net of accumulated depreciation and amortization of $23,228 and $21,707 | B11: 37595 | C11: 35486 | D11: =B11-C11 -> 2109 | E11: =D11/C11 -> 0.059431889 | G11: Aircraft maintenance materials and outside repairs | H11: 2616 | I11: 2432 | J11: =H11-I11 -> 184 | K11: =J11/I11 -> 0.075657895
A12: Operating lease right-of-use assets | B12: 6644 | C12: 7004 | D12: =B12-C12 -> -360 | E12: =D12/C12 -> -0.0513992 | G12: Depreciation and amortization | H12: 2513 | I12: 2341 | J12: =H12-I12 -> 172 | K12: =J12/I12 -> 0.073472875
A13: Goodwill | B13: 9753 | C13: 9753 | D13: =B13-C13 -> 0 | E13: =D13/C13 -> 0 | G13: Passenger commissions and other selling expenses | H13: 2485 | I13: 2334 | J13: =H13-I13 -> 151 | K13: =J13/I13 -> 0.064695801
A14: Identifiable intangibles, net of accumulated amortization of $919 and $911 | B14: 5975 | C14: 5983 | D14: =B14-C14 -> -8 | E14: =D14/C14 -> -0.0013371218 | G14: Regional carrier expense | H14: 2328 | I14: 2200 | J14: =H14-I14 -> 128 | K14: =J14/I14 -> 0.058181818
A15: Equity investments | B15: 2846 | C15: 3457 | D15: =B15-C15 -> -611 | E15: =D15/C15 -> -0.17674284 | G15: Passenger service | H15: 1788 | I15: 1750 | J15: =H15-I15 -> 38 | K15: =J15/I15 -> 0.021714286
A16: Other noncurrent assets | B16: 2715 | C16: 1692 | D16: =B16-C16 -> 1023 | E16: =D16/C16 -> 0.60460993 | G16: Profit sharing | H16: 1389 | I16: 1383 | J16: =H16-I16 -> 6 | K16: =J16/I16 -> 0.0043383948
A17: Total noncurrent assets | B17: 65528 | C17: 63375 | D17: =B17-C17 -> 2153 | E17: =D17/C17 -> 0.033972387 | G17: Aircraft rent | H17: 548 | I17: 532 | J17: =H17-I17 -> 16 | K17: =J17/I17 -> 0.030075188
A18: Total assets | B18: 75372 | C18: 73644 | D18: =B18-C18 -> 1728 | E18: =D18/C18 -> 0.023464233 | G18: Pilot agreement and related expenses | H18: 0 | I18: 864 | J18: =H18-I18 -> -864 | K18: =J18/I18 -> -1
A19: Current Liabilities: | G19: Other | H19: 2460 | I19: 2239 | J19: =H19-I19 -> 221 | K19: =J19/I19 -> 0.098704779
A20: Current maturities of debt and finance leases | B20: 2175 | C20: 2983 | D20: =B20-C20 -> -808 | E20: =D20/C20 -> -0.27086825 | G20: Total operating expense | H20: 55648 | I20: 52527 | J20: =H20-I20 -> 3121 | K20: =J20/I20 -> 0.059417062
A21: Current maturities of operating leases | B21: 763 | C21: 759 | D21: =B21-C21 -> 4 | E21: =D21/C21 -> 0.0052700922 | G21: Operating Income | H21: 5995 | I21: 5521 | J21: =H21-I21 -> 474 | K21: =J21/I21 -> 0.085854012
A22: Accounts payable | B22: 4650 | C22: 4446 | D22: =B22-C22 -> 204 | E22: =D22/C22 -> 0.045883941 | G22: Non-Operating (Expense)/Income:
A23: Accrued salaries and related benefits | B23: 4762 | C23: 4561 | D23: =B23-C23 -> 201 | E23: =D23/C23 -> 0.044069283 | G23: Interest expense, net | H23: -747 | I23: -834 | J23: =H23-I23 -> 87 | K23: =J23/I23 -> -0.10431655
A24: Fuel card obligation | B24: 1100 | C24: 1100 | D24: =B24-C24 -> 0 | E24: =D24/C24 -> 0 | G24: Gain/(loss) on investments, net | H24: -319 | I24: 1263 | J24: =H24-I24 -> -1582 | K24: =J24/I24 -> -1.2525732
A25: Other accrued liabilities | B25: 1812 | C25: 1617 | D25: =B25-C25 -> 195 | E25: =D25/C25 -> 0.12059369 | G25: Loss on extinguishment of debt | H25: -39 | I25: -63 | J25: =H25-I25 -> 24 | K25: =J25/I25 -> -0.38095238
A26: Total current liabilities | B26: 26670 | C26: 26418 | D26: =B26-C26 -> 252 | E26: =D26/C26 -> 0.0095389507 | G26: Miscellaneous, net | H26: -232 | I26: -279 | J26: =H26-I26 -> 47 | K26: =J26/I26 -> -0.16845878
A27: Noncurrent Liabilities: | G27: Total non-operating (expense)/income, net | H27: -1337 | I27: 87 | J27: =H27-I27 -> -1424 | K27: =J27/I27 -> -16.367816
A28: Debt and finance leases | B28: 14019 | C28: 17071 | D28: =B28-C28 -> -3052 | E28: =D28/C28 -> -0.17878273 | G28: Income Before Income Taxes | H28: 4658 | I28: 5608 | J28: =H28-I28 -> -950 | K28: =J28/I28 -> -0.16940086
A29: Pension, postretirement and related benefits | B29: 3144 | C29: 3601 | D29: =B29-C29 -> -457 | E29: =D29/C29 -> -0.12690919 | G29: Income Tax Provision | H29: -1201 | I29: -999 | J29: =H29-I29 -> -202 | K29: =J29/I29 -> 0.2022022
A30: Noncurrent operating leases | B30: 5814 | C30: 6468 | D30: =B30-C30 -> -654 | E30: =D30/C30 -> -0.10111317 | G30: Net Income | H30: 3457 | I30: 4609 | J30: =H30-I30 -> -1152 | K30: =J30/I30 -> -0.24994576
A31: Deferred income taxes, net | B31: 2176 | C31: 908 | D31: =B31-C31 -> 1268 | E31: =D31/C31 -> 1.3964758 | G31: Basic Earnings Per Share (USD per share) | H31: 5.39 | I31: 7.21 | J31: =H31-I31 -> -1.82 | K31: =J31/I31 -> -0.25242718
A32: Other noncurrent liabilities | B32: 3744 | C32: 3561 | D32: =B32-C32 -> 183 | E32: =D32/C32 -> 0.051390059 | G32: Diluted Earnings Per Share (USD per share) | H32: 5.33 | I32: 7.17 | J32: =H32-I32 -> -1.84 | K32: =J32/I32 -> -0.25662483
A33: Total noncurrent liabilities | B33: 33409 | C33: 36121 | D33: =B33-C33 -> -2712 | E33: =D33/C33 -> -0.075080978
A34: Commitments and Contingencies
A35: Stockholders' Equity:
A36: Common stock at $0.0001 par value; 1,500,000,000 shares authorized, 654,571,606 and 654,671,194 shares issued | B36: 0 | C36: 0 | D36: =B36-C36 -> 0
A37: Additional paid-in capital | B37: 11740 | C37: 11641 | D37: =B37-C37 -> 99 | E37: =D37/C37 -> 0.008504424
A38: Retained earnings | B38: 8783 | C38: 5650 | D38: =B38-C38 -> 3133 | E38: =D38/C38 -> 0.55451327
A39: Accumulated other comprehensive loss | B39: -4979 | C39: -5845 | D39: =B39-C39 -> 866 | E39: =D39/C39 -> -0.14816082
A40: Treasury stock, at cost, 8,098,971 and 11,224,246 shares | B40: -251 | C40: -341 | D40: =B40-C40 -> 90 | E40: =D40/C40 -> -0.26392962
...

Sheet Vertical Analysis
A1: Consolidated Balance Sheets - USD ($) | B1: Dec. 31, 2024 | C1: Dec. 31, 2023 | D1: Common Size Percents | G1: Competitor | I1: Consolidated Statements of Operations - USD ($) | J1: 12 Months Ended | L1: Common Size Percents | O1: Competitor
A2: $ in Millions | D2: 2024 | E2: 2023 | G2: 2024 | I2: $ in Millions | J2: Dec. 31, 2024 | K2: Dec. 31, 2023 | L2: 2024 | M2: 2023 | O2: 2024
A3: Current Assets: | G3: United Airlines | I3: Operating Revenue: | O3: United Airlines
A4: Cash and cash equivalents | B4: 3069 | C4: 2741 | D4: =B4/$B$18 -> 0.040718039 | E4: =C4/$C$18 -> 0.037219597 | G4: 0.118 | I4: Total operating revenue | J4: 61643 | K4: 58048 | L4: =J4/$J$4 -> 1 | M4: =K4/$K$4 -> 1 | O4: 1
A5: Short-term investments | B5: 0 | C5: 1127 | D5: =B5/$B$18 -> 0 | E5: =C5/$C$18 -> 0.015303351 | I5: Operating Expense:
A6: Accounts receivable, net of an allowance for uncollectible accounts of $18 and $17 | B6: 3224 | C6: 3130 | D6: =B6/$B$18 -> 0.042774505 | E6: =C6/$C$18 -> 0.042501765 | G6: 0.029 | I6: Salaries and related costs | J6: 16161 | K6: 14607 | L6: =J6/$J$4 -> 0.26217089 | M6: =K6/$K$4 -> 0.25163658
A7: Fuel, expendable parts and supplies inventories, net of an allowance for obsolescence of $120 and $123 | B7: 1428 | C7: 1314 | D7: =B7/$B$18 -> 0.018946028 | E7: =C7/$C$18 -> 0.017842594 | I7: Aircraft fuel and related taxes | J7: 10566 | K7: 11069 | L7: =J7/$J$4 -> 0.17140632 | M7: =K7/$K$4 -> 0.19068702
A8: Prepaid expenses and other | B8: 2123 | C8: 1957 | D8: =B8/$B$18 -> 0.028166959 | E8: =C8/$C$18 -> 0.026573787 | I8: Ancillary businesses and refinery | J8: 5416 | K8: 4172 | L8: =J8/$J$4 -> 0.087860747 | M8: =K8/$K$4 -> 0.071871555
A9: Total current assets | B9: 9844 | C9: 10269 | D9: =B9/$B$18 -> 0.13060553 | E9: =C9/$C$18 -> 0.13944109 | G9: 0.255 | I9: Contracted services | J9: 4228 | K9: 4041 | L9: =J9/$J$4 -> 0.068588485 | M9: =K9/$K$4 -> 0.069614802
A10: Noncurrent Assets: | I10: Landing fees and other rents | J10: 3150 | K10: 2563 | L10: =J10/$J$4 -> 0.051100693 | M10: =K10/$K$4 -> 0.044153115
A11: Property and equipment, net of accumulated depreciation and amortization of $23,228 and $21,707 | B11: 37595 | C11: 35486 | D11: =B11/$B$18 -> 0.49879266 | E11: =C11/$C$18 -> 0.48185867 | I11: Aircraft maintenance materials and outside repairs | J11: 2616 | K11: 2432 | L11: =J11/$J$4 -> 0.042437909 | M11: =K11/$K$4 -> 0.041896362
A12: Operating lease right-of-use assets | B12: 6644 | C12: 7004 | D12: =B12/$B$18 -> 0.088149445 | E12: =C12/$C$18 -> 0.095106187 | I12: Depreciation and amortization | J12: 2513 | K12: 2341 | L12: =J12/$J$4 -> 0.040766997 | M12: =K12/$K$4 -> 0.040328693
A13: Goodwill | B13: 9753 | C13: 9753 | D13: =B13/$B$18 -> 0.12939819 | E13: =C13/$C$18 -> 0.13243441 | I13: Passenger commissions and other selling expenses | J13: 2485 | K13: 2334 | L13: =J13/$J$4 -> 0.040312769 | M13: =K13/$K$4 -> 0.040208104
A14: Identifiable intangibles, net of accumulated amortization of $919 and $911 | B14: 5975 | C14: 5983 | D14: =B14/$B$18 -> 0.07927347 | E14: =C14/$C$18 -> 0.081242192 | I14: Regional carrier expense | J14: 2328 | K14: 2200 | L14: =J14/$J$4 -> 0.037765845 | M14: =K14/$K$4 -> 0.037899669
A15: Equity investments | B15: 2846 | C15: 3457 | D15: =B15/$B$18 -> 0.03775938 | E15: =C15/$C$18 -> 0.046942046 | I15: Passenger service | J15: 1788 | K15: 1750 | L15: =J15/$J$4 -> 0.029005727 | M15: =K15/$K$4 -> 0.030147464
A16: Other noncurrent assets | B16: 2715 | C16: 1692 | D16: =B16/$B$18 -> 0.036021334 | E16: =C16/$C$18 -> 0.022975395 | I16: Profit sharing | J16: 1389 | K16: 1383 | L16: =J16/$J$4 -> 0.022532972 | M16: =K16/$K$4 -> 0.02382511
A17: Total noncurrent assets | B17: 65528 | C17: 63375 | D17: =B17/$B$18 -> 0.86939447 | E17: =C17/$C$18 -> 0.86055891 | I17: Aircraft rent | J17: 548 | K17: 532 | L17: =J17/$J$4 -> 0.0088898983 | M17: =K17/$K$4 -> 0.0091648291
A18: Total assets | B18: 75372 | C18: 73644 | D18: =B18/$B$18 -> 1 | E18: =C18/$C$18 -> 1 | G18: 1 | I18: Pilot agreement and related expenses | J18: 0 | K18: 864 | L18: =J18/$J$4 -> 0 | M18: =K18/$K$4 -> 0.014884234
A19: Current Liabilities: | I19: Other | J19: 2460 | K19: 2239 | L19: =J19/$J$4 -> 0.039907208 | M19: =K19/$K$4 -> 0.038571527
A20: Current maturities of debt and finance leases | B20: 2175 | C20: 2983 | D20: =B20/$B$18 -> 0.02885687 | E20: =C20/$C$18 -> 0.040505676 | I20: Total operating expense | J20: 55648 | K20: 52527 | L20: =J20/$J$4 -> 0.90274646 | M20: =K20/$K$4 -> 0.90488906 | O20: 0.911
A21: Current maturities of operating leases | B21: 763 | C21: 759 | D21: =B21/$B$18 -> 0.010123123 | E21: =C21/$C$18 -> 0.010306339 | I21: Operating Income | J21: 5995 | K21: 5521 | L21: =J21/$J$4 -> 0.097253541 | M21: =K21/$K$4 -> 0.095110943 | O21: 0.089
A22: Accounts payable | B22: 4650 | C22: 4446 | D22: =B22/$B$18 -> 0.061693998 | E22: =C22/$C$18 -> 0.060371517 | I22: Non-Operating (Expense)/Income:
A23: Accrued salaries and related benefits | B23: 4762 | C23: 4561 | D23: =B23/$B$18 -> 0.063179961 | E23: =C23/$C$18 -> 0.061933083 | I23: Interest expense, net | J23: -747 | K23: -834 | L23: =J23/$J$4 -> -0.012118164 | M23: =K23/$K$4 -> -0.01436742
A24: Fuel card obligation | B24: 1100 | C24: 1100 | D24: =B24/$B$18 -> 0.014594279 | E24: =C24/$C$18 -> 0.014936723 | I24: Gain/(loss) on investments, net | J24: -319 | K24: 1263 | L24: =J24/$J$4 -> -0.005174959 | M24: =K24/$K$4 -> 0.021757856
A25: Other accrued liabilities | B25: 1812 | C25: 1617 | D25: =B25/$B$18 -> 0.024040758 | E25: =C25/$C$18 -> 0.021956982 | I25: Loss on extinguishment of debt | J25: -39 | K25: -63 | L25: =J25/$J$4 -> -0.00063267524 | M25: =K25/$K$4 -> -0.0010853087
A26: Total current liabilities | B26: 26670 | C26: 26418 | D26: =B26/$B$18 -> 0.35384493 | E26: =C26/$C$18 -> 0.35872576 | G26: 0.315 | I26: Miscellaneous, net | J26: -232 | K26: -279 | L26: =J26/$J$4 -> -0.0037636066 | M26: =K26/$K$4 -> -0.0048063671
A27: Noncurrent Liabilities: | I27: Total non-operating (expense)/income, net | J27: -1337 | K27: 87 | L27: =J27/$J$4 -> -0.021689405 | M27: =K27/$K$4 -> 0.0014987596
A28: Debt and finance leases | B28: 14019 | C28: 17071 | D28: =B28/$B$18 -> 0.18599745 | E28: =C28/$C$18 -> 0.23180436 | I28: Income Before Income Taxes | J28: 4658 | K28: 5608 | L28: =J28/$J$4 -> 0.075564135 | M28: =K28/$K$4 -> 0.096609702
A29: Pension, postretirement and related benefits | B29: 3144 | C29: 3601 | D29: =B29/$B$18 -> 0.041713103 | E29: =C29/$C$18 -> 0.048897398 | I29: Income Tax Provision | J29: -1201 | K29: -999 | L29: =J29/$J$4 -> -0.019483153 | M29: =K29/$K$4 -> -0.017209895
A30: Noncurrent operating leases | B30: 5814 | C30: 6468 | D30: =B30/$B$18 -> 0.077137399 | E30: =C30/$C$18 -> 0.087827929 | I30: Net Income | J30: 3457 | K30: 4609 | L30: =J30/$J$4 -> 0.056080982 | M30: =K30/$K$4 -> 0.079399807 | O30: 0.055
A31: Deferred income taxes, net | B31: 2176 | C31: 908 | D31: =B31/$B$18 -> 0.028870137 | E31: =C31/$C$18 -> 0.012329586 | I31: Basic Earnings Per Share (USD per share) | J31: 5.39 | K31: 7.21 | L31: =J31/$J$4 -> 8.7438963e-05 | M31: =K31/$K$4 -> 0.00012420755
A32: Other noncurrent liabilities | B32: 3744 | C32: 3561 | D32: =B32/$B$18 -> 0.049673619 | E32: =C32/$C$18 -> 0.048354245 | I32: Diluted Earnings Per Share (USD per share) | J32: 5.33 | K32: 7.17 | L32: =J32/$J$4 -> 8.6465617e-05 | M32: =K32/$K$4 -> 0.00012351847
A33: Total noncurrent liabilities | B33: 33409 | C33: 36121 | D33: =B33/$B$18 -> 0.44325479 | E33: =C33/$C$18 -> 0.49048123 | G33: 0.514
A34: Commitments and Contingencies
A35: Stockholders' Equity:
A36: Common stock at $0.0001 par value; 1,500,000,000 shares authorized, 654,571,606 and 654,671,194 shares issued | B36: 0 | C36: 0 | D36: =B36/$B$18 -> 0 | E36: =C36/$C$18 -> 0
A37: Additional paid-in capital | B37: 11740 | C37: 11641 | D37: =B37/$B$18 -> 0.15576076 | E37: =C37/$C$18 -> 0.15807126
A38: Retained earnings | B38: 8783 | C38: 5650 | D38: =B38/$B$18 -> 0.11652868 | E38: =C38/$C$18 -> 0.076720439
A39: Accumulated other comprehensive loss | B39: -4979 | C39: -5845 | D39: =B39/$B$18 -> -0.066059014 | E39: =C39/$C$18 -> -0.079368312
A40: Treasury stock, at cost, 8,098,971 and 11,224,246 shares | B40: -251 | C40: -341 | D40: =B40/$B$18 -> -0.0033301491 | E40: =C40/$C$18 -> -0.004630384
...

Sheet Ratio Analysis
C1: Delta | E1: 2024 | F1: 2023 | H1: Competitor
A2: Liquidity & Efficiency Ratios | H2: United Airlines
I3: Example of formula
B4: Current Ratio | C4: Current Assets / Current Liabilities | E4: ='Balance Sheet'!B9/'Balance Sheet'!B26 -> 0.36910386 | F4: ='Balance Sheet'!C9/'Balance Sheet'!C26 -> 0.38871224 | H4: 0.81
B6: Quick Ratio | C6: (Cash + Short Term investments + A/R) / Current Liabilities) | E6: =(('Balance Sheet'!B4+'Balance Sheet'!B5+'Balance Sheet'!B6)/'Balance Sheet'!B26) -> 0.23595801 | F6: =(('Balance Sheet'!C4+'Balance Sheet'!C5+'Balance Sheet'!C6)/'Balance Sheet'!C26) -> 0.26489515 | H6: 0.71
B8: Total Asset Turnover= | C8: Net Sales/Average total assets | E8: =('Income Statement'!B4/(('Balance Sheet'!B18+'Balance Sheet'!C18)/2)) -> 0.82733398 | F8: =('Income Statement'!C4/(('Balance Sheet'!C18+'Balance Sheet'!D18)/2)) -> 0.79554861 | H8: 0.786 | I8: =(Net Sales/((Current year total assets-previous year total assets)/2))
B10: Accounts Receivable Turnover | C10: Revenue / Average Accounts Receivable | E10: =('Income Statement'!B4/(('Balance Sheet'!B6+'Balance Sheet'!C6)/2)) -> 19.402896 | F10: =('Income Statement'!C4/(('Balance Sheet'!C6+'Balance Sheet'!D6)/2)) -> 18.410403 | H10: 28.12 | I10: =(Net Sales/((Current year accounts receivable-previous year accounts receivable)/2))
A12: Solvency
B13: Debt Ratio = | C13: Total Liabilities/Total Assets | E13: =(('Balance Sheet'!B26+'Balance Sheet'!B33)/'Balance Sheet'!B18) -> 0.79709972 | F13: =(('Balance Sheet'!C26+'Balance Sheet'!C33)/'Balance Sheet'!C18) -> 0.849207 | H13: 0.83
B15: Debt to Equity = | C15: Total Liabilities/Total Equity | E15: =('Balance Sheet'!B26+'Balance Sheet'!B33)/'Balance Sheet'!B41 -> 3.9285294 | F15: =('Balance Sheet'!C26+'Balance Sheet'!C33)/'Balance Sheet'!C41 -> 5.6316074 | H15: 4.85
B17: Times Interest Earned = | C17: Income before interst and income tax expense / Interest Expense | E17: ='Income Statement'!B21/'Income Statement'!B23 -> -8.0254351 | F17: ='Income Statement'!C21/'Income Statement'!C23 -> -6.6199041 | H17: 3.13 times
A19: Profitability
B20: Profit Margin Ratio = | C20: Net Income/Net Sales | E20: ='Income Statement'!B30/'Income Statement'!B4 -> 0.056080982 | F20: ='Income Statement'!C30/'Income Statement'!C4 -> 0.079399807 | H20: 0.0552
B22: Return on Total Assets = | C22: Net Income/ Average Total Assets | E22: =('Income Statement'!B30/(('Balance Sheet'!B18+'Balance Sheet'!C18)/2)) -> 0.046397702 | F22: =('Income Statement'!C30/(('Balance Sheet'!C18+'Balance Sheet'!D18)/2)) -> 0.063166406 | H22: 0.0434 | I22: =(Net Income/((Current year total assets-previous year total assets)/2))
B24: Return on Equity | C24: Net Income/Average Total Equity | E24: =('Income Statement'!B30/(('Balance Sheet'!B41+'Balance Sheet'!C41)/2)) -> 0.26191378 | F24: =('Income Statement'!C30/(('Balance Sheet'!C41+'Balance Sheet'!D41)/2)) -> 0.52117374 | H24: 0.28 | I24: =(Net Income/((Current year total equity-previous year total equity)/2))

Sheet Balance Sheet
A1: Consolidated Balance Sheets Delta Airlines- USD ($) | B1: Dec. 31, 2024 | C1: Dec. 31, 2023 | D1: Dec. 31, 2022
A2: $ in Millions
A3: Current Assets:
A4: Cash and cash equivalents | B4: 3069 | C4: 2741 | D4: 3266
A5: Short-term investments | B5: 0 | C5: 1127 | D5: 3268
A6: Accounts receivable, net of an allowance for uncollectible accounts of $18 and $17 | B6: 3224 | C6: 3130 | D6: 3176
A7: Fuel, expendable parts and supplies inventories, net of an allowance for obsolescence of $120 and $123 | B7: 1428 | C7: 1314 | D7: 1424
A8: Prepaid expenses and other | B8: 2123 | C8: 1957 | D8: 1877
A9: Total current assets | B9: 9844 | C9: 10269 | D9: 13011
A10: Noncurrent Assets:
A11: Property and equipment, net of accumulated depreciation and amortization of $23,228 and $21,707 | B11: 37595 | C11: 35486 | D11: 33109
A12: Operating lease right-of-use assets | B12: 6644 | C12: 7004 | D12: 7036
A13: Goodwill | B13: 9753 | C13: 9753 | D13: 9753
A14: Identifiable intangibles, net of accumulated amortization of $919 and $911 | B14: 5975 | C14: 5983 | D14: 5992
A15: Equity investments | B15: 2846 | C15: 3457 | D15: 2128
A16: Other noncurrent assets | B16: 2715 | C16: 1692 | D16: 1259
A17: Total noncurrent assets | B17: 65528 | C17: 63375 | D17: 59277
A18: Total assets | B18: 75372 | C18: 73644 | D18: 72288
A19: Current Liabilities:
A20: Current maturities of debt and finance leases | B20: 2175 | C20: 2983 | D20: 2359
A21: Current maturities of operating leases | B21: 763 | C21: 759 | D21: 714
A22: Accounts payable | B22: 4650 | C22: 4446 | D22: 5106
A23: Accrued salaries and related benefits | B23: 4762 | C23: 4561 | D23: 3288
A24: Fuel card obligation | B24: 1100 | C24: 1100 | D24: 1100
A25: Other accrued liabilities | B25: 1812 | C25: 1617 | D25: 1779
A26: Total current liabilities | B26: 26670 | C26: 26418 | D26: 25940
A27: Noncurrent Liabilities:
A28: Debt and finance leases | B28: 14019 | C28: 17071 | D28: 20671
A29: Pension, postretirement and related benefits | B29: 3144 | C29: 3601 | D29: 3707
A30: Noncurrent operating leases | B30: 5814 | C30: 6468 | D30: 6866
A31: Deferred income taxes, net | B31: 2176 | C31: 908 | D31: 24
A32: Other noncurrent liabilities | B32: 3744 | C32: 3561 | D32: 4050
A33: Total noncurrent liabilities | B33: 33409 | C33: 36121 | D33: 39766
A34: Commitments and Contingencies
A35: Stockholders' Equity:
A36: Common stock at $0.0001 par value; 1,500,000,000 shares authorized, 654,571,606 and 654,671,194 shares issued | B36: 0 | C36: 0 | D36: 0
A37: Additional paid-in capital | B37: 11740 | C37: 11641 | D37: 11526
A38: Retained earnings | B38: 8783 | C38: 5650 | D38: 1170
A39: Accumulated other comprehensive loss | B39: -4979 | C39: -5845 | D39: -5801
A40: Treasury stock, at cost, 8,098,971 and 11,224,246 shares | B40: -251 | C40: -341 | D40: -313
...

Sheet Income Statement
A1: Consolidated Statements of Operations Delta Airlines- USD ($) | B1: 12 Months Ended
A2: $ in Millions | B2: Dec. 31, 2024 | C2: Dec. 31, 2023
A3: Operating Revenue:
A4: Total operating revenue | B4: 61643 | C4: 58048
A5: Operating Expense:
A6: Salaries and related costs | B6: 16161 | C6: 14607
A7: Aircraft fuel and related taxes | B7: 10566 | C7: 11069
A8: Ancillary businesses and refinery | B8: 5416 | C8: 4172
A9: Contracted services | B9: 4228 | C9: 4041
A10: Landing fees and other rents | B10: 3150 | C10: 2563
A11: Aircraft maintenance materials and outside repairs | B11: 2616 | C11: 2432
A12: Depreciation and amortization | B12: 2513 | C12: 2341
A13: Passenger commissions and other selling expenses | B13: 2485 | C13: 2334
A14: Regional carrier expense | B14: 2328 | C14: 2200
A15: Passenger service | B15: 1788 | C15: 1750
A16: Profit sharing | B16: 1389 | C16: 1383
A17: Aircraft rent | B17: 548 | C17: 532
... A21: Operating Income | B21: 5995 | C21: 5521
A22: Non-Operating (Expense)/Income:
A23: Interest expense, net | B23: -747 | C23: -834
A24: Gain/(loss) on investments, net | B24: -319 | C24: 1263
A25: Loss on extinguishment of debt | B25: -39 | C25: -63
A26: Miscellaneous, net | B26: -232 | C26: -279
A27: Total non-operating (expense)/income, net | B27: -1337 | C27: 87
A28: Income Before Income Taxes | B28: 4658 | C28: 5608
A29: Income Tax Provision | B29: -1201 | C29: -999
A30: Net Income | B30: 3457 | C30: 4609
A31: Basic Earnings Per Share (USD per share) | B31: 5.39 | C31: 7.21
A32: Diluted Earnings Per Share (USD per share) | B32: 5.33 | C32: 7.17
